Workbook

Sheet Scenario Summary
B2: Logistics Decision Engine - Scenario Data
B4: Engine Constants & Assumptions | F4: Active Scenario Context
B5: Parameter | C5: Value | D5: Unit / Context | F5: Variable | G5: Config Value
B6: SHIFT_HOURS | C6: 8 | D6: Hours per driver shift | F6: Current Weather Condition | G6: heavy_snow
B7: DELIVERIES_PER_DRIVER_PER_SHIFT | C7: 8 | D7: Target volume per driver | F7: Active Traffic/Event Severity | G7: major
B8: EXPRESS_SLA_HOURS | C8: 2 | D8: SLA delivery window | F8: Target Order Volume | G8: 50
B9: STANDARD_SLA_HOURS | C9: 8 | D9: SLA delivery window | F9: Base Shift Drivers Available | G9: 10
B10: DRIVER_SHIFT_COST | C10: 120 | D10: Cost per driver shift ($) | F10: Express Order Tier Mix Share | G10: 40.0%
B11: EXPRESS_PENALTY | C11: 25 | D11: SLA breach penalty ($) | F11: Primary Affected Zone | G11: central
B12: STANDARD_PENALTY | C12: 8 | D12: SLA breach penalty ($) | F12: Affected Zone Share | G12: 40.0%
B13: WEATHER_MULTIPLIER (heavy_snow) | C13: 0.6 | D13: Capacity adjustment multiplier
B14: TRAFFIC_RISK_SCORE (major) | C14: 75 | D14: Risk index score (0-100)
B15: WEATHER_RISK_SCORE (heavy_snow) | C15: 90 | D15: Risk index score (0-100) | F15: Live Sheet Aggregations
B16: RISK_WEIGHTS (weather/traffic/load) | C16: 40% / 30% / 30% | D16: Engine calculation weights | F16: Total Drivers On Shift | G16: ='Integrated Drivers'!E17
F17: Total Orders Tracked | G17: =COUNTA('Orders Data'!B5:B54)

Sheet Orders Data
B2: Active Shift Delivery Orders Ledger
B4: Order ID | C4: Service Tier | D4: Destination Zone | E4: SLA Delivery Window (Hrs) | F4: Breach Penalty Risk
B5: ORD-000 | C5: standard | D5: central | E5: =IF(C5="express", 'Scenario Summary'!C6, 'Scenario Summary'!C7) | F5: =IF(C5="express", 'Scenario Summary'!C8, 'Scenario Summary'!C9)
B6: ORD-001 | C6: standard | D6: central | E6: =IF(C6="express", 'Scenario Summary'!C6, 'Scenario Summary'!C7) | F6: =IF(C6="express", 'Scenario Summary'!C8, 'Scenario Summary'!C9)
B7: ORD-002 | C7: standard | D7: west | E7: =IF(C7="express", 'Scenario Summary'!C6, 'Scenario Summary'!C7) | F7: =IF(C7="express", 'Scenario Summary'!C8, 'Scenario Summary'!C9)
B8: ORD-003 | C8: express | D8: central | E8: =IF(C8="express", 'Scenario Summary'!C6, 'Scenario Summary'!C7) | F8: =IF(C8="express", 'Scenario Summary'!C8, 'Scenario Summary'!C9)
B9: ORD-004 | C9: standard | D9: south | E9: =IF(C9="express", 'Scenario Summary'!C6, 'Scenario Summary'!C7) | F9: =IF(C9="express", 'Scenario Summary'!C8, 'Scenario Summary'!C9)
B10: ORD-005 | C10: express | D10: central | E10: =IF(C10="express", 'Scenario Summary'!C6, 'Scenario Summary'!C7) | F10: =IF(C10="express", 'Scenario Summary'!C8, 'Scenario Summary'!C9)
B11: ORD-006 | C11: express | D11: central | E11: =IF(C11="express", 'Scenario Summary'!C6, 'Scenario Summary'!C7) | F11: =IF(C11="express", 'Scenario Summary'!C8, 'Scenario Summary'!C9)
B12: ORD-007 | C12: standard | D12: central | E12: =IF(C12="express", 'Scenario Summary'!C6, 'Scenario Summary'!C7) | F12: =IF(C12="express", 'Scenario Summary'!C8, 'Scenario Summary'!C9)
B13: ORD-008 | C13: standard | D13: north | E13: =IF(C13="express", 'Scenario Summary'!C6, 'Scenario Summary'!C7) | F13: =IF(C13="express", 'Scenario Summary'!C8, 'Scenario Summary'!C9)
B14: ORD-009 | C14: express | D14: central | E14: =IF(C14="express", 'Scenario Summary'!C6, 'Scenario Summary'!C7) | F14: =IF(C14="express", 'Scenario Summary'!C8, 'Scenario Summary'!C9)
B15: ORD-010 | C15: standard | D15: central | E15: =IF(C15="express", 'Scenario Summary'!C6, 'Scenario Summary'!C7) | F15: =IF(C15="express", 'Scenario Summary'!C8, 'Scenario Summary'!C9)
B16: ORD-011 | C16: standard | D16: west | E16: =IF(C16="express", 'Scenario Summary'!C6, 'Scenario Summary'!C7) | F16: =IF(C16="express", 'Scenario Summary'!C8, 'Scenario Summary'!C9)
B17: ORD-012 | C17: standard | D17: north | E17: =IF(C17="express", 'Scenario Summary'!C6, 'Scenario Summary'!C7) | F17: =IF(C17="express", 'Scenario Summary'!C8, 'Scenario Summary'!C9)
B18: ORD-013 | C18: standard | D18: south | E18: =IF(C18="express", 'Scenario Summary'!C6, 'Scenario Summary'!C7) | F18: =IF(C18="express", 'Scenario Summary'!C8, 'Scenario Summary'!C9)
B19: ORD-014 | C19: express | D19: north | E19: =IF(C19="express", 'Scenario Summary'!C6, 'Scenario Summary'!C7) | F19: =IF(C19="express", 'Scenario Summary'!C8, 'Scenario Summary'!C9)
B20: ORD-015 | C20: express | D20: central | E20: =IF(C20="express", 'Scenario Summary'!C6, 'Scenario Summary'!C7) | F20: =IF(C20="express", 'Scenario Summary'!C8, 'Scenario Summary'!C9)
B21: ORD-016 | C21: standard | D21: east | E21: =IF(C21="express", 'Scenario Summary'!C6, 'Scenario Summary'!C7) | F21: =IF(C21="express", 'Scenario Summary'!C8, 'Scenario Summary'!C9)
B22: ORD-017 | C22: express | D22: east | E22: =IF(C22="express", 'Scenario Summary'!C6, 'Scenario Summary'!C7) | F22: =IF(C22="express", 'Scenario Summary'!C8, 'Scenario Summary'!C9)
B23: ORD-018 | C23: standard | D23: south | E23: =IF(C23="express", 'Scenario Summary'!C6, 'Scenario Summary'!C7) | F23: =IF(C23="express", 'Scenario Summary'!C8, 'Scenario Summary'!C9)
B24: ORD-019 | C24: express | D24: central | E24: =IF(C24="express", 'Scenario Summary'!C6, 'Scenario Summary'!C7) | F24: =IF(C24="express", 'Scenario Summary'!C8, 'Scenario Summary'!C9)
B25: ORD-020 | C25: standard | D25: central | E25: =IF(C25="express", 'Scenario Summary'!C6, 'Scenario Summary'!C7) | F25: =IF(C25="express", 'Scenario Summary'!C8, 'Scenario Summary'!C9)
B26: ORD-021 | C26: standard | D26: west | E26: =IF(C26="express", 'Scenario Summary'!C6, 'Scenario Summary'!C7) | F26: =IF(C26="express", 'Scenario Summary'!C8, 'Scenario Summary'!C9)
B27: ORD-022 | C27: standard | D27: central | E27: =IF(C27="express", 'Scenario Summary'!C6, 'Scenario Summary'!C7) | F27: =IF(C27="express", 'Scenario Summary'!C8, 'Scenario Summary'!C9)
B28: ORD-023 | C28: standard | D28: east | E28: =IF(C28="express", 'Scenario Summary'!C6, 'Scenario Summary'!C7) | F28: =IF(C28="express", 'Scenario Summary'!C8, 'Scenario Summary'!C9)
B29: ORD-024 | C29: express | D29: central | E29: =IF(C29="express", 'Scenario Summary'!C6, 'Scenario Summary'!C7) | F29: =IF(C29="express", 'Scenario Summary'!C8, 'Scenario Summary'!C9)
B30: ORD-025 | C30: express | D30: central | E30: =IF(C30="express", 'Scenario Summary'!C6, 'Scenario Summary'!C7) | F30: =IF(C30="express", 'Scenario Summary'!C8, 'Scenario Summary'!C9)
B31: ORD-026 | C31: standard | D31: central | E31: =IF(C31="express", 'Scenario Summary'!C6, 'Scenario Summary'!C7) | F31: =IF(C31="express", 'Scenario Summary'!C8, 'Scenario Summary'!C9)
B32: ORD-027 | C32: standard | D32: central | E32: =IF(C32="express", 'Scenario Summary'!C6, 'Scenario Summary'!C7) | F32: =IF(C32="express", 'Scenario Summary'!C8, 'Scenario Summary'!C9)
B33: ORD-028 | C33: express | D33: south | E33: =IF(C33="express", 'Scenario Summary'!C6, 'Scenario Summary'!C7) | F33: =IF(C33="express", 'Scenario Summary'!C8, 'Scenario Summary'!C9)
B34: ORD-029 | C34: standard | D34: east | E34: =IF(C34="express", 'Scenario Summary'!C6, 'Scenario Summary'!C7) | F34: =IF(C34="express", 'Scenario Summary'!C8, 'Scenario Summary'!C9)
B35: ORD-030 | C35: express | D35: central | E35: =IF(C35="express", 'Scenario Summary'!C6, 'Scenario Summary'!C7) | F35: =IF(C35="express", 'Scenario Summary'!C8, 'Scenario Summary'!C9)
B36: ORD-031 | C36: express | D36: north | E36: =IF(C36="express", 'Scenario Summary'!C6, 'Scenario Summary'!C7) | F36: =IF(C36="express", 'Scenario Summary'!C8, 'Scenario Summary'!C9)
B37: ORD-032 | C37: standard | D37: west | E37: =IF(C37="express", 'Scenario Summary'!C6, 'Scenario Summary'!C7) | F37: =IF(C37="express", 'Scenario Summary'!C8, 'Scenario Summary'!C9)
B38: ORD-033 | C38: standard | D38: north | E38: =IF(C38="express", 'Scenario Summary'!C6, 'Scenario Summary'!C7) | F38: =IF(C38="express", 'Scenario Summary'!C8, 'Scenario Summary'!C9)
B39: ORD-034 | C39: express | D39: south | E39: =IF(C39="express", 'Scenario Summary'!C6, 'Scenario Summary'!C7) | F39: =IF(C39="express", 'Scenario Summary'!C8, 'Scenario Summary'!C9)
B40: ORD-035 | C40: standard | D40: south | E40: =IF(C40="express", 'Scenario Summary'!C6, 'Scenario Summary'!C7) | F40: =IF(C40="express", 'Scenario Summary'!C8, 'Scenario Summary'!C9)
B41: ORD-036 | C41: standard | D41: west | E41: =IF(C41="express", 'Scenario Summary'!C6, 'Scenario Summary'!C7) | F41: =IF(C41="express", 'Scenario Summary'!C8, 'Scenario Summary'!C9)
B42: ORD-037 | C42: express | D42: east | E42: =IF(C42="express", 'Scenario Summary'!C6, 'Scenario Summary'!C7) | F42: =IF(C42="express", 'Scenario Summary'!C8, 'Scenario Summary'!C9)
...

Sheet Integrated Drivers
B2: Integrated Fleet Capacity & Weather Exposure Risk
B4: Driver ID | C4: Status | D4: Base Shift (Hrs) | E4: Weather Scenario | F4: Shift Cost | G4: Weather Multiplier | H4: Degraded Capacity (Deliveries) | I4: Risk Profile Score
B5: DRV-000 | C5: ACTIVE | D5: ='Scenario Summary'!C6 | E5: ='Scenario Summary'!C13 | F5: ='Scenario Summary'!C10 | G5: ='Scenario Summary'!C13 | H5: ='Scenario Summary'!C7*G5 | I5: ='Scenario Summary'!C15
B6: DRV-001 | C6: ACTIVE | D6: ='Scenario Summary'!C6 | E6: ='Scenario Summary'!C13 | F6: ='Scenario Summary'!C10 | G6: ='Scenario Summary'!C13 | H6: ='Scenario Summary'!C7*G6 | I6: ='Scenario Summary'!C15
B7: DRV-002 | C7: ACTIVE | D7: ='Scenario Summary'!C6 | E7: ='Scenario Summary'!C13 | F7: ='Scenario Summary'!C10 | G7: ='Scenario Summary'!C13 | H7: ='Scenario Summary'!C7*G7 | I7: ='Scenario Summary'!C15
B8: DRV-003 | C8: ACTIVE | D8: ='Scenario Summary'!C6 | E8: ='Scenario Summary'!C13 | F8: ='Scenario Summary'!C10 | G8: ='Scenario Summary'!C13 | H8: ='Scenario Summary'!C7*G8 | I8: ='Scenario Summary'!C15
B9: DRV-004 | C9: ACTIVE | D9: ='Scenario Summary'!C6 | E9: ='Scenario Summary'!C13 | F9: ='Scenario Summary'!C10 | G9: ='Scenario Summary'!C13 | H9: ='Scenario Summary'!C7*G9 | I9: ='Scenario Summary'!C15
B10: DRV-005 | C10: ACTIVE | D10: ='Scenario Summary'!C6 | E10: ='Scenario Summary'!C13 | F10: ='Scenario Summary'!C10 | G10: ='Scenario Summary'!C13 | H10: ='Scenario Summary'!C7*G10 | I10: ='Scenario Summary'!C15
B11: DRV-006 | C11: ACTIVE | D11: ='Scenario Summary'!C6 | E11: ='Scenario Summary'!C13 | F11: ='Scenario Summary'!C10 | G11: ='Scenario Summary'!C13 | H11: ='Scenario Summary'!C7*G11 | I11: ='Scenario Summary'!C15
B12: DRV-007 | C12: ACTIVE | D12: ='Scenario Summary'!C6 | E12: ='Scenario Summary'!C13 | F12: ='Scenario Summary'!C10 | G12: ='Scenario Summary'!C13 | H12: ='Scenario Summary'!C7*G12 | I12: ='Scenario Summary'!C15
B13: DRV-008 | C13: ACTIVE | D13: ='Scenario Summary'!C6 | E13: ='Scenario Summary'!C13 | F13: ='Scenario Summary'!C10 | G13: ='Scenario Summary'!C13 | H13: ='Scenario Summary'!C7*G13 | I13: ='Scenario Summary'!C15
B14: DRV-009 | C14: ACTIVE | D14: ='Scenario Summary'!C6 | E14: ='Scenario Summary'!C13 | F14: ='Scenario Summary'!C10 | G14: ='Scenario Summary'!C13 | H14: ='Scenario Summary'!C7*G14 | I14: ='Scenario Summary'!C15
B15: Total Fleet Operational Cost | F15: =SUM(F5:F14)
B16: Total Fleet Deliveries Capacity | H16: =SUM(H5:H14)
E17: =SUM(F5:F14)
